Workbook
Name TAG: Table1[Tagging No.]

Sheet Validations
A1: Mcfl123 | B1: Company Name | D1: Product | E1: Code | G1: Office | H1: Code | J1: Ownership | L1: Category | N1: Type of Transaction
B2: MCFL | D2: CPU | E2: DT | G2: Head Office | H2: HO | J2: Owned | L2: Software | N2: Opening Stock
B3: MBHPL | D3: Desktop/Monitor | E3: TFT | G3: Vile Parle | H3: VLP | J3: Leased | L3: Hardware | N3: Addition
B4: HBTS | D4: Mouse | E4: 103 | G4: Vashi | H4: VSH | N4: Internal Transfer
B5: MEPL | D5: Keyboard | E5: 104 | G5: Virar | H5: VR | N5: Sold/Expired
B6: MFPL | D6: Laptop | E6: LP | G6: Malad | H6: MDD | N6: Scrapped
B7: DET | D7: Adaptor | E7: ADP | G7: Dombivli | H7: DI
B8: FOY | D8: Printer | E8: PRI | G8: Dharavi | H8: DH
D9: Scanner | E9: SCAN | G9: Panvel | H9: PNVL
D10: Mobile | E10: MOB | G10: Surat | H10: ST
D11: CCTV Camera | E11: CAM | G11: Rajkot | H11: RJT
D12: CCTV | E12: NVR | G12: Mira Road | H12: MIRA
D13: Biomax | E13: BIO | G13: Badlapur | H13: BUD
D14: Firewall | E14: FW | G14: Kalyan | H14: KYN
D15: Server | E15: SVR | G15: Kalavad | H15: KLVD
D16: All In One | E16: 115 | G16: Vasai | H16: BSR
D17: Switch | E17: SWI | G17: Surendranagar | H17: SUNR
D18: Router | E18: ROU | G18: Prabhadevi | H18: PBHD
D19: Webcam | E19: WEB | G19: JaiHindCottage | H19: JHC
D20: NAS Box | E20: NAS | G20: Thane | H20: TNA
D21: Mobile Charger | E21: MCHG | G21: Mavdi | H21: MVD
D22: TAB | E22: TAB | G22: Ambernath | H22: ABH
D23: External HDD | E23: EHDD | G23: Kankroli | H23: KDL
D24: Headset | E24: 123 | G24: Sunderwas | H24: SDW
D25: Weighing Machine | E25: 124 | G25: Bhayandar | H25: BYR
D26: Note Counting Machine | E26: 125 | G26: Nathdwara | H26: NDT
D27: Landline Phone | E27: TEL | G27: Karjat | H27: KJT
D28: Access Point | E28: AP
D29: Guardwell Vault | E29: 128
D30: UPS | E30: UPS
D31: UPS Battery | E31: UPSB
D32: HDD | E32: 131
D33: SSD | E33: 132
D34: Alarm System | E34: AS
D35: IPAD | E35: IPAD
D36: IPAD Charger | E36: IPADC

Sheet Code File
A1: Sr | B1: URN | C1: Date of Acquisition | D1: Year of Acquistion | E1: Company | F1: Location | G1: Location Code | H1: Product | I1: Product Code | J1: Product Serial Number | K1: Tagging No. | L1: Assign To | M1: Purchased From | N1: Warranty Expiry | O1: Status
A2: =ROW(Table1[[#This Row],[Product Serial Number]])-ROW(Table1[[#Headers],[URN]]) -> 1 | B2: =ROW(Table1[[#This Row],[Product Serial Number]])-ROW(Table1[[#Headers],[URN]])+999 -> 1000 | C2: 45887 | D2: =YEAR(Table1[[#This Row],[Date of Acquisition]]) -> 2025 | E2: MCFL | F2: Nathdwara | G2: =VLOOKUP(F2,Validations!$G$2:$H$27,2,0) -> NDT | H2: Biomax | I2: =VLOOKUP(H2,Validations!$D$2:$E$36,2,0) -> BIO | J2: AMDB24111500028 | K2: =IF(ISLOGICAL(C2),0,(E2&I2&B2)) -> MCFLBIO1000 | L2: Nathdwara Branch | M2: ACG Telecom
A3: =ROW(Table1[[#This Row],[Product Serial Number]])-ROW(Table1[[#Headers],[URN]]) -> 2 | B3: =ROW(Table1[[#This Row],[Product Serial Number]])-ROW(Table1[[#Headers],[URN]])+999 -> 1001 | C3: 45887 | D3: =YEAR(Table1[[#This Row],[Date of Acquisition]]) -> 2025 | E3: MCFL | F3: Nathdwara | G3: =VLOOKUP(F3,Validations!$G$2:$H$27,2,0) -> NDT | H3: Biomax | I3: =VLOOKUP(H3,Validations!$D$2:$E$36,2,0) -> BIO | J3: AMDB24052200858 | K3: =IF(ISLOGICAL(C3),0,(E3&I3&B3)) -> MCFLBIO1001 | L3: Nathdwara Branch | M3: ACG Telecom
A4: =ROW(Table1[[#This Row],[Product Serial Number]])-ROW(Table1[[#Headers],[URN]]) -> 3 | B4: =ROW(Table1[[#This Row],[Product Serial Number]])-ROW(Table1[[#Headers],[URN]])+999 -> 1002 | C4: 45887 | D4: =YEAR(Table1[[#This Row],[Date of Acquisition]]) -> 2025 | E4: MCFL | F4: Nathdwara | G4: =VLOOKUP(F4,Validations!$G$2:$H$27,2,0) -> NDT | H4: Alarm System | I4: =VLOOKUP(H4,Validations!$D$2:$E$36,2,0) -> AS | J4: Q37689185 | K4: =IF(ISLOGICAL(C4),0,(E4&I4&B4)) -> MCFLAS1002 | L4: Nathdwara Branch | M4: ACG Telecom
A5: =ROW(Table1[[#This Row],[Product Serial Number]])-ROW(Table1[[#Headers],[URN]]) -> 4 | B5: =ROW(Table1[[#This Row],[Product Serial Number]])-ROW(Table1[[#Headers],[URN]])+999 -> 1003 | C5: 45882 | D5: =YEAR(Table1[[#This Row],[Date of Acquisition]]) -> 2025 | E5: MCFL | F5: Nathdwara | G5: =VLOOKUP(F5,Validations!$G$2:$H$27,2,0) -> NDT | H5: CCTV Camera | I5: =VLOOKUP(H5,Validations!$D$2:$E$36,2,0) -> CAM | J5: FV5562000 | K5: =IF(ISLOGICAL(C5),0,(E5&I5&B5)) -> MCFLCAM1003 | L5: Nathdwara Branch | M5: MRK Computers
A6: =ROW(Table1[[#This Row],[Product Serial Number]])-ROW(Table1[[#Headers],[URN]]) -> 5 | B6: =ROW(Table1[[#This Row],[Product Serial Number]])-ROW(Table1[[#Headers],[URN]])+999 -> 1004 | C6: 45882 | D6: =YEAR(Table1[[#This Row],[Date of Acquisition]]) -> 2025 | E6: MCFL | F6: Nathdwara | G6: =VLOOKUP(F6,Validations!$G$2:$H$27,2,0) -> NDT | H6: CCTV Camera | I6: =VLOOKUP(H6,Validations!$D$2:$E$36,2,0) -> CAM | J6: FV5561977 | K6: =IF(ISLOGICAL(C6),0,(E6&I6&B6)) -> MCFLCAM1004 | L6: Nathdwara Branch | M6: MRK Computers
A7: =ROW(Table1[[#This Row],[Product Serial Number]])-ROW(Table1[[#Headers],[URN]]) -> 6 | B7: =ROW(Table1[[#This Row],[Product Serial Number]])-ROW(Table1[[#Headers],[URN]])+999 -> 1005 | C7: 45882 | D7: =YEAR(Table1[[#This Row],[Date of Acquisition]]) -> 2025 | E7: MCFL | F7: Nathdwara | G7: =VLOOKUP(F7,Validations!$G$2:$H$27,2,0) -> NDT | H7: CCTV Camera | I7: =VLOOKUP(H7,Validations!$D$2:$E$36,2,0) -> CAM | J7: FV5562002 | K7: =IF(ISLOGICAL(C7),0,(E7&I7&B7)) -> MCFLCAM1005 | L7: Nathdwara Branch | M7: MRK Computers
A8: =ROW(Table1[[#This Row],[Product Serial Number]])-ROW(Table1[[#Headers],[URN]]) -> 7 | B8: =ROW(Table1[[#This Row],[Product Serial Number]])-ROW(Table1[[#Headers],[URN]])+999 -> 1006 | C8: 45882 | D8: =YEAR(Table1[[#This Row],[Date of Acquisition]]) -> 2025 | E8: MCFL | F8: Nathdwara | G8: =VLOOKUP(F8,Validations!$G$2:$H$27,2,0) -> NDT | H8: CCTV Camera | I8: =VLOOKUP(H8,Validations!$D$2:$E$36,2,0) -> CAM | J8: FV3220092 | K8: =IF(ISLOGICAL(C8),0,(E8&I8&B8)) -> MCFLCAM1006 | L8: Nathdwara Branch | M8: MRK Computers
A9: =ROW(Table1[[#This Row],[Product Serial Number]])-ROW(Table1[[#Headers],[URN]]) -> 8 | B9: =ROW(Table1[[#This Row],[Product Serial Number]])-ROW(Table1[[#Headers],[URN]])+999 -> 1007 | C9: 45882 | D9: =YEAR(Table1[[#This Row],[Date of Acquisition]]) -> 2025 | E9: MCFL | F9: Nathdwara | G9: =VLOOKUP(F9,Validations!$G$2:$H$27,2,0) -> NDT | H9: CCTV Camera | I9: =VLOOKUP(H9,Validations!$D$2:$E$36,2,0) -> CAM | J9: FV3220117 | K9: =IF(ISLOGICAL(C9),0,(E9&I9&B9)) -> MCFLCAM1007 | L9: Nathdwara Branch | M9: MRK Computers
A10: =ROW(Table1[[#This Row],[Product Serial Number]])-ROW(Table1[[#Headers],[URN]]) -> 9 | B10: =ROW(Table1[[#This Row],[Product Serial Number]])-ROW(Table1[[#Headers],[URN]])+999 -> 1008 | C10: 45882 | D10: =YEAR(Table1[[#This Row],[Date of Acquisition]]) -> 2025 | E10: MCFL | F10: Nathdwara | G10: =VLOOKUP(F10,Validations!$G$2:$H$27,2,0) -> NDT | H10: CCTV Camera | I10: =VLOOKUP(H10,Validations!$D$2:$E$36,2,0) -> CAM | J10: FV3220139 | K10: =IF(ISLOGICAL(C10),0,(E10&I10&B10)) -> MCFLCAM1008 | L10: Nathdwara Branch | M10: MRK Computers
A11: =ROW(Table1[[#This Row],[Product Serial Number]])-ROW(Table1[[#Headers],[URN]]) -> 10 | B11: =ROW(Table1[[#This Row],[Product Serial Number]])-ROW(Table1[[#Headers],[URN]])+999 -> 1009 | C11: 45882 | D11: =YEAR(Table1[[#This Row],[Date of Acquisition]]) -> 2025 | E11: MCFL | F11: Nathdwara | G11: =VLOOKUP(F11,Validations!$G$2:$H$27,2,0) -> NDT | H11: CCTV Camera | I11: =VLOOKUP(H11,Validations!$D$2:$E$36,2,0) -> CAM | J11: FV3220049 | K11: =IF(ISLOGICAL(C11),0,(E11&I11&B11)) -> MCFLCAM1009 | L11: Nathdwara Branch | M11: MRK Computers
A12: =ROW(Table1[[#This Row],[Product Serial Number]])-ROW(Table1[[#Headers],[URN]]) -> 11 | B12: =ROW(Table1[[#This Row],[Product Serial Number]])-ROW(Table1[[#Headers],[URN]])+999 -> 1010 | C12: 45882 | D12: =YEAR(Table1[[#This Row],[Date of Acquisition]]) -> 2025 | E12: MCFL | F12: Nathdwara | G12: =VLOOKUP(F12,Validations!$G$2:$H$27,2,0) -> NDT | H12: CCTV Camera | I12: =VLOOKUP(H12,Validations!$D$2:$E$36,2,0) -> CAM | J12: FV3220128 | K12: =IF(ISLOGICAL(C12),0,(E12&I12&B12)) -> MCFLCAM1010 | L12: Nathdwara Branch | M12: MRK Computers
A13: =ROW(Table1[[#This Row],[Product Serial Number]])-ROW(Table1[[#Headers],[URN]]) -> 12 | B13: =ROW(Table1[[#This Row],[Product Serial Number]])-ROW(Table1[[#Headers],[URN]])+999 -> 1011 | C13: 45883 | D13: =YEAR(Table1[[#This Row],[Date of Acquisition]]) -> 2025 | E13: MCFL | F13: Nathdwara | G13: =VLOOKUP(F13,Validations!$G$2:$H$27,2,0) -> NDT | H13: Printer | I13: =VLOOKUP(H13,Validations!$D$2:$E$36,2,0) -> PRI | J13: CNBRT5N0V1 | K13: =IF(ISLOGICAL(C13),0,(E13&I13&B13)) -> MCFLPRI1011 | L13: Nathdwara Branch | M13: MRK Computers
... A15: =ROW(Table1[[#This Row],[Product Serial Number]])-ROW(Table1[[#Headers],[URN]]) -> 14 | B15: =ROW(Table1[[#This Row],[Product Serial Number]])-ROW(Table1[[#Headers],[URN]])+999 -> 1013 | C15: 45882 | D15: =YEAR(Table1[[#This Row],[Date of Acquisition]]) -> 2025 | E15: MCFL | F15: Nathdwara | G15: =VLOOKUP(F15,Validations!$G$2:$H$27,2,0) -> NDT | H15: Switch | I15: =VLOOKUP(H15,Validations!$D$2:$E$36,2,0) -> SWI | J15: S08G2241203473 | K15: =IF(ISLOGICAL(C15),0,(E15&I15&B15)) -> MCFLSWI1013 | L15: Nathdwara Branch | M15: MRK Computers
A16: =ROW(Table1[[#This Row],[Product Serial Number]])-ROW(Table1[[#Headers],[URN]]) -> 15 | B16: =ROW(Table1[[#This Row],[Product Serial Number]])-ROW(Table1[[#Headers],[URN]])+999 -> 1014 | D16: =YEAR(Table1[[#This Row],[Date of Acquisition]]) -> 1900 | E16: MCFL | F16: Nathdwara | G16: =VLOOKUP(F16,Validations!$G$2:$H$27,2,0) -> NDT | H16: Mobile | I16: =VLOOKUP(H16,Validations!$D$2:$E$36,2,0) -> MOB | K16: =IF(ISLOGICAL(C16),0,(E16&I16&B16)) -> MCFLMOB1014 | L16: Nathdwara Branch
A17: =ROW(Table1[[#This Row],[Product Serial Number]])-ROW(Table1[[#Headers],[URN]]) -> 16 | B17: =ROW(Table1[[#This Row],[Product Serial Number]])-ROW(Table1[[#Headers],[URN]])+999 -> 1015 | C17: 45887 | D17: =YEAR(Table1[[#This Row],[Date of Acquisition]]) -> 2025 | E17: MCFL | F17: Karjat | G17: =VLOOKUP(F17,Validations!$G$2:$H$27,2,0) -> KJT | H17: Mobile | I17: =VLOOKUP(H17,Validations!$D$2:$E$36,2,0) -> MOB | J17: R9ZY30VM02N | K17: =IF(ISLOGICAL(C17),0,(E17&I17&B17)) -> MCFLMOB1015 | L17: Karjat Branch | M17: Flipkart
A18: =ROW(Table1[[#This Row],[Product Serial Number]])-ROW(Table1[[#Headers],[URN]]) -> 17 | B18: =ROW(Table1[[#This Row],[Product Serial Number]])-ROW(Table1[[#Headers],[URN]])+999 -> 1016 | C18: 45890 | D18: =YEAR(Table1[[#This Row],[Date of Acquisition]]) -> 2025 | E18: MCFL | F18: Karjat | G18: =VLOOKUP(F18,Validations!$G$2:$H$27,2,0) -> KJT | H18: Printer | I18: =VLOOKUP(H18,Validations!$D$2:$E$36,2,0) -> PRI | J18: CNBRT3P2DP | K18: =IF(ISLOGICAL(C18),0,(E18&I18&B18)) -> MCFLPRI1016 | L18: Karjat Branch | M18: ACG Telecom
A19: =ROW(Table1[[#This Row],[Product Serial Number]])-ROW(Table1[[#Headers],[URN]]) -> 18 | B19: =ROW(Table1[[#This Row],[Product Serial Number]])-ROW(Table1[[#Headers],[URN]])+999 -> 1017 | C19: 45887 | D19: =YEAR(Table1[[#This Row],[Date of Acquisition]]) -> 2025 | E19: MCFL | F19: Karjat | G19: =VLOOKUP(F19,Validations!$G$2:$H$27,2,0) -> KJT | H19: CCTV | I19: =VLOOKUP(H19,Validations!$D$2:$E$36,2,0) -> NVR | J19: FR1139376 | K19: =IF(ISLOGICAL(C19),0,(E19&I19&B19)) -> MCFLNVR1017 | L19: Karjat Branch | M19: ACG Telecom
A20: =ROW(Table1[[#This Row],[Product Serial Number]])-ROW(Table1[[#Headers],[URN]]) -> 19 | B20: =ROW(Table1[[#This Row],[Product Serial Number]])-ROW(Table1[[#Headers],[URN]])+999 -> 1018 | C20: 45887 | D20: =YEAR(Table1[[#This Row],[Date of Acquisition]]) -> 2025 | E20: MCFL | F20: Karjat | G20: =VLOOKUP(F20,Validations!$G$2:$H$27,2,0) -> KJT | H20: CCTV Camera | I20: =VLOOKUP(H20,Validations!$D$2:$E$36,2,0) -> CAM | J20: AG9447112 | K20: =IF(ISLOGICAL(C20),0,(E20&I20&B20)) -> MCFLCAM1018 | L20: Karjat Branch | M20: ACG Telecom
A21: =ROW(Table1[[#This Row],[Product Serial Number]])-ROW(Table1[[#Headers],[URN]]) -> 20 | B21: =ROW(Table1[[#This Row],[Product Serial Number]])-ROW(Table1[[#Headers],[URN]])+999 -> 1019 | C21: 45887 | D21: =YEAR(Table1[[#This Row],[Date of Acquisition]]) -> 2025 | E21: MCFL | F21: Karjat | G21: =VLOOKUP(F21,Validations!$G$2:$H$27,2,0) -> KJT | H21: CCTV Camera | I21: =VLOOKUP(H21,Validations!$D$2:$E$36,2,0) -> CAM | J21: AG9447439 | K21: =IF(ISLOGICAL(C21),0,(E21&I21&B21)) -> MCFLCAM1019 | L21: Karjat Branch | M21: ACG Telecom
A22: =ROW(Table1[[#This Row],[Product Serial Number]])-ROW(Table1[[#Headers],[URN]]) -> 21 | B22: =ROW(Table1[[#This Row],[Product Serial Number]])-ROW(Table1[[#Headers],[URN]])+999 -> 1020 | C22: 45887 | D22: =YEAR(Table1[[#This Row],[Date of Acquisition]]) -> 2025 | E22: MCFL | F22: Karjat | G22: =VLOOKUP(F22,Validations!$G$2:$H$27,2,0) -> KJT | H22: CCTV Camera | I22: =VLOOKUP(H22,Validations!$D$2:$E$36,2,0) -> CAM | J22: AG9447209 | K22: =IF(ISLOGICAL(C22),0,(E22&I22&B22)) -> MCFLCAM1020 | L22: Karjat Branch | M22: ACG Telecom
A23: =ROW(Table1[[#This Row],[Product Serial Number]])-ROW(Table1[[#Headers],[URN]]) -> 22 | B23: =ROW(Table1[[#This Row],[Product Serial Number]])-ROW(Table1[[#Headers],[URN]])+999 -> 1021 | C23: 45887 | D23: =YEAR(Table1[[#This Row],[Date of Acquisition]]) -> 2025 | E23: MCFL | F23: Karjat | G23: =VLOOKUP(F23,Validations!$G$2:$H$27,2,0) -> KJT | H23: CCTV Camera | I23: =VLOOKUP(H23,Validations!$D$2:$E$36,2,0) -> CAM | J23: AW0881697 | K23: =IF(ISLOGICAL(C23),0,(E23&I23&B23)) -> MCFLCAM1021 | L23: Karjat Branch | M23: ACG Telecom
A24: =ROW(Table1[[#This Row],[Product Serial Number]])-ROW(Table1[[#Headers],[URN]]) -> 23 | B24: =ROW(Table1[[#This Row],[Product Serial Number]])-ROW(Table1[[#Headers],[URN]])+999 -> 1022 | C24: 45887 | D24: =YEAR(Table1[[#This Row],[Date of Acquisition]]) -> 2025 | E24: MCFL | F24: Karjat | G24: =VLOOKUP(F24,Validations!$G$2:$H$27,2,0) -> KJT | H24: CCTV Camera | I24: =VLOOKUP(H24,Validations!$D$2:$E$36,2,0) -> CAM | J24: AG9447461 | K24: =IF(ISLOGICAL(C24),0,(E24&I24&B24)) -> MCFLCAM1022 | L24: Karjat Branch | M24: ACG Telecom
A25: =ROW(Table1[[#This Row],[Product Serial Number]])-ROW(Table1[[#Headers],[URN]]) -> 24 | B25: =ROW(Table1[[#This Row],[Product Serial Number]])-ROW(Table1[[#Headers],[URN]])+999 -> 1023 | C25: 45887 | D25: =YEAR(Table1[[#This Row],[Date of Acquisition]]) -> 2025 | E25: MCFL | F25: Karjat | G25: =VLOOKUP(F25,Validations!$G$2:$H$27,2,0) -> KJT | H25: CCTV Camera | I25: =VLOOKUP(H25,Validations!$D$2:$E$36,2,0) -> CAM | J25: AG9447455 | K25: =IF(ISLOGICAL(C25),0,(E25&I25&B25)) -> MCFLCAM1023 | L25: Karjat Branch | M25: ACG Telecom
A26: =ROW(Table1[[#This Row],[Product Serial Number]])-ROW(Table1[[#Headers],[URN]]) -> 25 | B26: =ROW(Table1[[#This Row],[Product Serial Number]])-ROW(Table1[[#Headers],[URN]])+999 -> 1024 | C26: 45887 | D26: =YEAR(Table1[[#This Row],[Date of Acquisition]]) -> 2025 | E26: MCFL | F26: Karjat | G26: =VLOOKUP(F26,Validations!$G$2:$H$27,2,0) -> KJT | H26: Alarm System | I26: =VLOOKUP(H26,Validations!$D$2:$E$36,2,0) -> AS | J26: Q34225152 | K26: =IF(ISLOGICAL(C26),0,(E26&I26&B26)) -> MCFLAS1024 | L26: Karjat Branch | M26: ACG Telecom
A27: =ROW(Table1[[#This Row],[Product Serial Number]])-ROW(Table1[[#Headers],[URN]]) -> 26 | B27: =ROW(Table1[[#This Row],[Product Serial Number]])-ROW(Table1[[#Headers],[URN]])+999 -> 1025 | C27: 45887 | D27: =YEAR(Table1[[#This Row],[Date of Acquisition]]) -> 2025 | E27: MCFL | F27: Karjat | G27: =VLOOKUP(F27,Validations!$G$2:$H$27,2,0) -> KJT | H27: Switch | I27: =VLOOKUP(H27,Validations!$D$2:$E$36,2,0) -> SWI | J27: 22352F3003350 | K27: =IF(ISLOGICAL(C27),0,(E27&I27&B27)) -> MCFLSWI1025 | L27: Karjat Branch | M27: ACG Telecom
A28: =ROW(Table1[[#This Row],[Product Serial Number]])-ROW(Table1[[#Headers],[URN]]) -> 27 | B28: =ROW(Table1[[#This Row],[Product Serial Number]])-ROW(Table1[[#Headers],[URN]])+999 -> 1026 | C28: 45887 | D28: =YEAR(Table1[[#This Row],[Date of Acquisition]]) -> 2025 | E28: MCFL | F28: Karjat | G28: =VLOOKUP(F28,Validations!$G$2:$H$27,2,0) -> KJT | H28: Switch | I28: =VLOOKUP(H28,Validations!$D$2:$E$36,2,0) -> SWI | J28: 2025048231345 | K28: =IF(ISLOGICAL(C28),0,(E28&I28&B28)) -> MCFLSWI1026 | L28: Karjat Branch | M28: ACG Telecom
... A31: =ROW(Table1[[#This Row],[Product Serial Number]])-ROW(Table1[[#Headers],[URN]]) -> 30 | B31: =ROW(Table1[[#This Row],[Product Serial Number]])-ROW(Table1[[#Headers],[URN]])+999 -> 1029 | C31: 45887 | D31: =YEAR(Table1[[#This Row],[Date of Acquisition]]) -> 2025 | E31: MCFL | F31: Karjat | G31: =VLOOKUP(F31,Validations!$G$2:$H$27,2,0) -> KJT | H31: CCTV Camera | I31: =VLOOKUP(H31,Validations!$D$2:$E$36,2,0) -> CAM | J31: AG9447454 | K31: =IF(ISLOGICAL(C31),0,(E31&I31&B31)) -> MCFLCAM1029 | L31: Karjat Branch | M31: ACG Telecom
A32: =ROW(Table1[[#This Row],[Product Serial Number]])-ROW(Table1[[#Headers],[URN]]) -> 31 | B32: =ROW(Table1[[#This Row],[Product Serial Number]])-ROW(Table1[[#Headers],[URN]])+999 -> 1030 | C32: 45882 | D32: =YEAR(Table1[[#This Row],[Date of Acquisition]]) -> 2025 | E32: MCFL | F32: Nathdwara | G32: =VLOOKUP(F32,Validations!$G$2:$H$27,2,0) -> NDT | H32: Switch | I32: =VLOOKUP(H32,Validations!$D$2:$E$36,2,0) -> SWI | K32: =IF(ISLOGICAL(C32),0,(E32&I32&B32)) -> MCFLSWI1030 | L32: Nathdwara Branch | M32: MRK Computers
A33: =ROW(Table1[[#This Row],[Product Serial Number]])-ROW(Table1[[#Headers],[URN]]) -> 32 | B33: =ROW(Table1[[#This Row],[Product Serial Number]])-ROW(Table1[[#Headers],[URN]])+999 -> 1031 | C33: 45868 | D33: =YEAR(Table1[[#This Row],[Date of Acquisition]]) -> 2025 | E33: MCFL | F33: Nathdwara | G33: =VLOOKUP(F33,Validations!$G$2:$H$27,2,0) -> NDT | H33: Laptop | I33: =VLOOKUP(H33,Validations!$D$2:$E$36,2,0) -> LP | J33: CY42Z64 | K33: =IF(ISLOGICAL(C33),0,(E33&I33&B33)) -> MCFLLP1031 | L33: Nathdwara Branch | M33: Softlink Technosys
A34: =ROW(Table1[[#This Row],[Product Serial Number]])-ROW(Table1[[#Headers],[URN]]) -> 33 | B34: =ROW(Table1[[#This Row],[Product Serial Number]])-ROW(Table1[[#Headers],[URN]])+999 -> 1032 | C34: 45868 | D34: =YEAR(Table1[[#This Row],[Date of Acquisition]]) -> 2025 | E34: MCFL | F34: Nathdwara | G34: =VLOOKUP(F34,Validations!$G$2:$H$27,2,0) -> NDT | H34: Adaptor | I34: =VLOOKUP(H34,Validations!$D$2:$E$36,2,0) -> ADP | J34: CN-07JHD3-CH600-4AE-0AZI-A02 | K34: =IF(ISLOGICAL(C34),0,(E34&I34&B34)) -> MCFLADP1032 | L34: Nathdwara Branch | M34: Softlink Technosys
A35: =ROW(Table1[[#This Row],[Product Serial Number]])-ROW(Table1[[#Headers],[URN]]) -> 34 | B35: =ROW(Table1[[#This Row],[Product Serial Number]])-ROW(Table1[[#Headers],[URN]])+999 -> 1033 | C35: 45868 | D35: =YEAR(Table1[[#This Row],[Date of Acquisition]]) -> 2025 | E35: MCFL | F35: Nathdwara | G35: =VLOOKUP(F35,Validations!$G$2:$H$27,2,0) -> NDT | H35: Laptop | I35: =VLOOKUP(H35,Validations!$D$2:$E$36,2,0) -> LP | J35: G5MDT74 | K35: =IF(ISLOGICAL(C35),0,(E35&I35&B35)) -> MCFLLP1033 | L35: Nathdwara Branch | M35: Softlink Technosys
A36: =ROW(Table1[[#This Row],[Product Serial Number]])-ROW(Table1[[#Headers],[URN]]) -> 35 | B36: =ROW(Table1[[#This Row],[Product Serial Number]])-ROW(Table1[[#Headers],[URN]])+999 -> 1034 | C36: 45868 | D36: =YEAR(Table1[[#This Row],[Date of Acquisition]]) -> 2025 | E36: MCFL | F36: Nathdwara | G36: =VLOOKUP(F36,Validations!$G$2:$H$27,2,0) -> NDT | H36: Adaptor | I36: =VLOOKUP(H36,Validations!$D$2:$E$36,2,0) -> ADP | J36: CN-07JHD3-CH600-4C9-0HW0-A02 | K36: =IF(ISLOGICAL(C36),0,(E36&I36&B36)) -> MCFLADP1034 | L36: Nathdwara Branch | M36: Softlink Technosys
A37: =ROW(Table1[[#This Row],[Product Serial Number]])-ROW(Table1[[#Headers],[URN]]) -> 36 | B37: =ROW(Table1[[#This Row],[Product Serial Number]])-ROW(Table1[[#Headers],[URN]])+999 -> 1035 | C37: 45868 | D37: =YEAR(Table1[[#This Row],[Date of Acquisition]]) -> 2025 | E37: MCFL | F37: Nathdwara | G37: =VLOOKUP(F37,Validations!$G$2:$H$27,2,0) -> NDT | H37: Laptop | I37: =VLOOKUP(H37,Validations!$D$2:$E$36,2,0) -> LP | J37: 3NVHY64 | K37: =IF(ISLOGICAL(C37),0,(E37&I37&B37)) -> MCFLLP1035 | L37: Nathdwara Branch | M37: Softlink Technosys
A38: =ROW(Table1[[#This Row],[Product Serial Number]])-ROW(Table1[[#Headers],[URN]]) -> 37 | B38: =ROW(Table1[[#This Row],[Product Serial Number]])-ROW(Table1[[#Headers],[URN]])+999 -> 1036 | C38: 45868 | D38: =YEAR(Table1[[#This Row],[Date of Acquisition]]) -> 2025 | E38: MCFL | F38: Nathdwara | G38: =VLOOKUP(F38,Validations!$G$2:$H$27,2,0) -> NDT | H38: Adaptor | I38: =VLOOKUP(H38,Validations!$D$2:$E$36,2,0) -> ADP | J38: CN-03PHNW-LOC00-4AI-0BB3-A02 | K38: =IF(ISLOGICAL(C38),0,(E38&I38&B38)) -> MCFLADP1036 | L38: Nathdwara Branch | M38: Softlink Technosys
A39: =ROW(Table1[[#This Row],[Product Serial Number]])-ROW(Table1[[#Headers],[URN]]) -> 38 | B39: =ROW(Table1[[#This Row],[Product Serial Number]])-ROW(Table1[[#Headers],[URN]])+999 -> 1037 | C39: 45868 | D39: =YEAR(Table1[[#This Row],[Date of Acquisition]]) -> 2025 | E39: MCFL | F39: Karjat | G39: =VLOOKUP(F39,Validations!$G$2:$H$27,2,0) -> KJT | H39: Laptop | I39: =VLOOKUP(H39,Validations!$D$2:$E$36,2,0) -> LP | J39: 58WVX64 | K39: =IF(ISLOGICAL(C39),0,(E39&I39&B39)) -> MCFLLP1037 | L39: Karjat Branch | M39: Softlink Technosys
A40: =ROW(Table1[[#This Row],[Product Serial Number]])-ROW(Table1[[#Headers],[URN]]) -> 39 | B40: =ROW(Table1[[#This Row],[Product Serial Number]])-ROW(Table1[[#Headers],[URN]])+999 -> 1038 | C40: 45868 | D40: =YEAR(Table1[[#This Row],[Date of Acquisition]]) -> 2025 | E40: MCFL | F40: Karjat | G40: =VLOOKUP(F40,Validations!$G$2:$H$27,2,0) -> KJT | H40: Adaptor | I40: =VLOOKUP(H40,Validations!$D$2:$E$36,2,0) -> ADP | J40: CN-0G4G24-DES00-495-EMOI-A02 | K40: =IF(ISLOGICAL(C40),0,(E40&I40&B40)) -> MCFLADP1038 | L40: Karjat Branch | M40: Softlink Technosys
A41: =ROW(Table1[[#This Row],[Product Serial Number]])-ROW(Table1[[#Headers],[URN]]) -> 40 | B41: =ROW(Table1[[#This Row],[Product Serial Number]])-ROW(Table1[[#Headers],[URN]])+999 -> 1039 | C41: 45868 | D41: =YEAR(Table1[[#This Row],[Date of Acquisition]]) -> 2025 | E41: MCFL | F41: Karjat | G41: =VLOOKUP(F41,Validations!$G$2:$H$27,2,0) -> KJT | H41: Laptop | I41: =VLOOKUP(H41,Validations!$D$2:$E$36,2,0) -> LP | J41: 4ZSC864 | K41: =IF(ISLOGICAL(C41),0,(E41&I41&B41)) -> MCFLLP1039 | L41: Karjat Branch | M41: Softlink Technosys
A42: =ROW(Table1[[#This Row],[Product Serial Number]])-ROW(Table1[[#Headers],[URN]]) -> 41 | B42: =ROW(Table1[[#This Row],[Product Serial Number]])-ROW(Table1[[#Headers],[URN]])+999 -> 1040 | C42: 45868 | D42: =YEAR(Table1[[#This Row],[Date of Acquisition]]) -> 2025 | E42: MCFL | F42: Karjat | G42: =VLOOKUP(F42,Validations!$G$2:$H$27,2,0) -> KJT | H42: Adaptor | I42: =VLOOKUP(H42,Validations!$D$2:$E$36,2,0) -> ADP | J42: CN-07JHD3-CH600-494-0UUN-A02 | K42: =IF(ISLOGICAL(C42),0,(E42&I42&B42)) -> MCFLADP1040 | L42: Karjat Branch | M42: Softlink Technosys
A43: =ROW(Table1[[#This Row],[Product Serial Number]])-ROW(Table1[[#Headers],[URN]]) -> 42 | B43: =ROW(Table1[[#This Row],[Product Serial Number]])-ROW(Table1[[#Headers],[URN]])+999 -> 1041 | C43: 45868 | D43: =YEAR(Table1[[#This Row],[Date of Acquisition]]) -> 2025 | E43: MCFL | F43: Karjat | G43: =VLOOKUP(F43,Validations!$G$2:$H$27,2,0) -> KJT | H43: Laptop | I43: =VLOOKUP(H43,Validations!$D$2:$E$36,2,0) -> LP | J43: G9WVX64 | K43: =IF(ISLOGICAL(C43),0,(E43&I43&B43)) -> MCFLLP1041 | L43: Karjat Branch | M43: Softlink Technosys
...

Sheet TagTheAsset
A1: Sr. No. | B1: Tag No. | C1: Ownership | D1: Category | E1: Product | F1: Product Code | G1: Product Description | H1: Brand Name | I1: Serial Number-1 | J1: Model | K1: Tech-Configuration | L1: Windows 10 Pro, 64 Bit | M1: Remark (If any) | N1: Cost of Asset | O1: Document Reference
A2: =ROW(TagTheAsset!$B2)-ROW(TagTheAsset!$A$1) -> 1 | B2: =Table1[[#This Row],[Tagging No.]] -> MCFLBIO1000 | C2: Owned | D2: Hardware | E2: =Table1[[#This Row],[Product]] -> Biomax | F2: =VLOOKUP(Table5[[#This Row],[Product]],Table6[],2,0) -> BIO | H2: HP | I2: =Table1[[#This Row],[Product Serial Number]] -> AMDB24111500028 | J2: Dell optiplex 390 | K2: i3- 9th Gen, 4GB RAM, 1TB HDD | L2: Windows 10 Professional Service Pack 1, 64 Bit | N2: 34000 | O2: Invoice
A3: =ROW(TagTheAsset!$B3)-ROW(TagTheAsset!$A$1) -> 2 | B3: =Table1[[#This Row],[Tagging No.]] -> MCFLBIO1001 | C3: Owned | D3: Hardware | E3: =Table1[[#This Row],[Product]] -> Biomax | F3: =VLOOKUP(Table5[[#This Row],[Product]],Table6[],2,0) -> BIO | H3: HP | I3: =Table1[[#This Row],[Product Serial Number]] -> AMDB24052200858 | J3: HP Pro 3330 MT | K3: i3-3220 CPU @ 3.30GHZ, 2GB RAM, 500GB HDD | L3: Windows 7 Professional Service Pack 1, 32 Bit | N3: 30476 | O3: Invoice(Desktop Bill)
A4: =ROW(TagTheAsset!$B4)-ROW(TagTheAsset!$A$1) -> 3 | B4: =Table1[[#This Row],[Tagging No.]] -> MCFLAS1002 | C4: Owned | D4: Hardware | E4: =Table1[[#This Row],[Product]] -> Alarm System | F4: =VLOOKUP(Table5[[#This Row],[Product]],Table6[],2,0) -> AS | H4: HP | I4: =Table1[[#This Row],[Product Serial Number]] -> Q37689185 | J4: Dell optiplex 390 | K4: i3- 9th Gen, 4GB RAM, 1TB HDD | L4: Windows 10 Professional Service Pack 1, 64 Bit | N4: 34000 | O4: Invoice
A5: =ROW(TagTheAsset!$B5)-ROW(TagTheAsset!$A$1) -> 4 | B5: =Table1[[#This Row],[Tagging No.]] -> MCFLCAM1003 | C5: Owned | D5: Hardware | E5: =Table1[[#This Row],[Product]] -> CCTV Camera | F5: =VLOOKUP(Table5[[#This Row],[Product]],Table6[],2,0) -> CAM | H5: HP | I5: =Table1[[#This Row],[Product Serial Number]] -> FV5562000 | J5: Dell optiplex 390 | K5: i3- 9th Gen, 4GB RAM, 1TB HDD | L5: Windows 10 Professional Service Pack 1, 64 Bit | N5: 34000 | O5: Invoice
A6: =ROW(TagTheAsset!$B6)-ROW(TagTheAsset!$A$1) -> 5 | B6: =Table1[[#This Row],[Tagging No.]] -> MCFLCAM1004 | C6: Owned | D6: Hardware | E6: =Table1[[#This Row],[Product]] -> CCTV Camera | F6: =VLOOKUP(Table5[[#This Row],[Product]],Table6[],2,0) -> CAM | H6: HP | I6: =Table1[[#This Row],[Product Serial Number]] -> FV5561977 | J6: HP Pro 3330 MT | K6: i3-3220 CPU @ 3.30GHZ, 2GB RAM, 500GB HDD | L6: Windows 10 Professional Service Pack 1, 64 Bit | N6: 30476 | O6: Invoice(Desktop Bill)
A7: =ROW(TagTheAsset!$B7)-ROW(TagTheAsset!$A$1) -> 6 | B7: =Table1[[#This Row],[Tagging No.]] -> MCFLCAM1005 | C7: Owned | D7: Hardware | E7: =Table1[[#This Row],[Product]] -> CCTV Camera | F7: =VLOOKUP(Table5[[#This Row],[Product]],Table6[],2,0) -> CAM | H7: HP | I7: =Table1[[#This Row],[Product Serial Number]] -> FV5562002 | J7: HP Pro 3330 MT | K7: i3-3220 CPU @ 3.30GHZ, 2GB RAM, 500GB HDD | L7: Windows 10 Professional Service Pack 1, 64 Bit | N7: 30476 | O7: Invoice(Desktop Bill)
A8: =ROW(TagTheAsset!$B8)-ROW(TagTheAsset!$A$1) -> 7 | B8: =Table1[[#This Row],[Tagging No.]] -> MCFLCAM1006 | C8: Owned | D8: Hardware | E8: =Table1[[#This Row],[Product]] -> CCTV Camera | F8: =VLOOKUP(Table5[[#This Row],[Product]],Table6[],2,0) -> CAM | H8: HP | I8: =Table1[[#This Row],[Product Serial Number]] -> FV3220092 | J8: Dell optiplex 390 | K8: i3- 9th Gen, 4GB RAM, 1TB HDD | L8: Windows 10 Professional Service Pack 1, 64 Bit | N8: 34000 | O8: Invoice
A9: =ROW(TagTheAsset!$B9)-ROW(TagTheAsset!$A$1) -> 8 | B9: =Table1[[#This Row],[Tagging No.]] -> MCFLCAM1007 | C9: Owned | D9: Hardware | E9: =Table1[[#This Row],[Product]] -> CCTV Camera | F9: =VLOOKUP(Table5[[#This Row],[Product]],Table6[],2,0) -> CAM | H9: HP | I9: =Table1[[#This Row],[Product Serial Number]] -> FV3220117 | J9: HP Pro 3330 MT | K9: i3-3220 CPU @ 3.30GHZ, 4GB RAM, 500GB HDD | L9: Windows 10 Professional Service Pack 1, 64 Bit | N9: 30476 | O9: Invoice(Desktop Bill)
A10: =ROW(TagTheAsset!$B10)-ROW(TagTheAsset!$A$1) -> 9 | B10: =Table1[[#This Row],[Tagging No.]] -> MCFLCAM1008 | C10: Owned | D10: Hardware | E10: =Table1[[#This Row],[Product]] -> CCTV Camera | F10: =VLOOKUP(Table5[[#This Row],[Product]],Table6[],2,0) -> CAM | H10: HP | I10: =Table1[[#This Row],[Product Serial Number]] -> FV3220139 | J10: HP Pro 3330 MT | K10: i5-3470 CPU @ 3.20GHZ, 8GB RAM, 1TBB HDD | L10: Windows 10 Professional Service Pack 1, 64 Bit | N10: 30476 | O10: Invoice(Desktop Bill)
A11: =ROW(TagTheAsset!$B11)-ROW(TagTheAsset!$A$1) -> 10 | B11: =Table1[[#This Row],[Tagging No.]] -> MCFLCAM1009 | C11: Owned | D11: Hardware | E11: =Table1[[#This Row],[Product]] -> CCTV Camera | F11: =VLOOKUP(Table5[[#This Row],[Product]],Table6[],2,0) -> CAM | H11: HP | I11: =Table1[[#This Row],[Product Serial Number]] -> FV3220049 | J11: HP Pro 3330 MT | K11: i3-3220 CPU @ 3.30GHZ, 16GB RAM, 1TB HDD | L11: Windows 10 Professional, 64 Bit | N11: 30476 | O11: Invoice(Desktop Bill)
A12: =ROW(TagTheAsset!$B12)-ROW(TagTheAsset!$A$1) -> 11 | B12: =Table1[[#This Row],[Tagging No.]] -> MCFLCAM1010 | C12: Owned | D12: Hardware | E12: =Table1[[#This Row],[Product]] -> CCTV Camera | F12: =VLOOKUP(Table5[[#This Row],[Product]],Table6[],2,0) -> CAM | H12: HP | I12: =Table1[[#This Row],[Product Serial Number]] -> FV3220128 | J12: HP Pro 3330 MT | K12: i3-3220 CPU @ 3.30GHZ, 4GB RAM, 500GB HDD | L12: Windows 10 Professional Service Pack 1, 32 Bit | N12: 30476 | O12: Invoice(Desktop Bill)
A13: =ROW(TagTheAsset!$B13)-ROW(TagTheAsset!$A$1) -> 12 | B13: =Table1[[#This Row],[Tagging No.]] -> MCFLPRI1011 | C13: Owned | D13: Hardware | E13: =Table1[[#This Row],[Product]] -> Printer | F13: =VLOOKUP(Table5[[#This Row],[Product]],Table6[],2,0) -> PRI | H13: HP | I13: =Table1[[#This Row],[Product Serial Number]] -> CNBRT5N0V1 | J13: Dell optiplex 390 | K13: i3- 9th Gen, 4GB RAM, 1TB HDD | L13: Windows 10 Professional Service Pack 1, 64 Bit | N13: 34000 | O13: Invoice
... A16: =ROW(TagTheAsset!$B16)-ROW(TagTheAsset!$A$1) -> 15 | B16: =Table1[[#This Row],[Tagging No.]] -> MCFLMOB1014 | C16: Owned | D16: Hardware | E16: =Table1[[#This Row],[Product]] -> Mobile | F16: =VLOOKUP(Table5[[#This Row],[Product]],Table6[],2,0) -> MOB | H16: HP | I16: =Table1[[#This Row],[Product Serial Number]] -> 0 | J16: HP Pro 3330 MT | K16: i3-3220 CPU @ 3.30GHZ, 2GB RAM, 500GB HDD | L16: Windows 10 Professional Service Pack 1, 32 Bit | N16: 30476 | O16: Invoice(Desktop Bill)
A17: =ROW(TagTheAsset!$B17)-ROW(TagTheAsset!$A$1) -> 16 | B17: =Table1[[#This Row],[Tagging No.]] -> MCFLMOB1015 | C17: Owned | D17: Hardware | E17: =Table1[[#This Row],[Product]] -> Mobile | F17: =VLOOKUP(Table5[[#This Row],[Product]],Table6[],2,0) -> MOB | H17: HP | I17: =Table1[[#This Row],[Product Serial Number]] -> R9ZY30VM02N | J17: HP Pro 3330 MT
A18: =ROW(TagTheAsset!$B18)-ROW(TagTheAsset!$A$1) -> 17 | B18: =Table1[[#This Row],[Tagging No.]] -> MCFLPRI1016 | C18: Owned | D18: Hardware | E18: =Table1[[#This Row],[Product]] -> Printer | F18: =VLOOKUP(Table5[[#This Row],[Product]],Table6[],2,0) -> PRI | H18: HP | I18: =Table1[[#This Row],[Product Serial Number]] -> CNBRT3P2DP | J18: HP Pro 3330 MT | K18: i3-3220 CPU @ 3.30GHZ, 6GB RAM, 500GB HDD | L18: Windows 7 Professional Service Pack 1, 64 Bit | N18: 30476 | O18: Invoice(Desktop Bill)
A19: =ROW(TagTheAsset!$B19)-ROW(TagTheAsset!$A$1) -> 18 | B19: =Table1[[#This Row],[Tagging No.]] -> MCFLNVR1017 | C19: Owned | D19: Hardware | E19: =Table1[[#This Row],[Product]] -> CCTV | F19: =VLOOKUP(Table5[[#This Row],[Product]],Table6[],2,0) -> NVR | H19: HP | I19: =Table1[[#This Row],[Product Serial Number]] -> FR1139376 | J19: HP Pro 3330 MT | K19: i3-3220 CPU @ 3.30GHZ, 2GB RAM, 500GB HDD | L19: Windows 10 Professional Service Pack 1, 32 Bit | N19: 30476 | O19: Invoice(Desktop Bill)
A20: =ROW(TagTheAsset!$B20)-ROW(TagTheAsset!$A$1) -> 19 | B20: =Table1[[#This Row],[Tagging No.]] -> MCFLCAM1018 | C20: Owned | D20: Hardware | E20: =Table1[[#This Row],[Product]] -> CCTV Camera | F20: =VLOOKUP(Table5[[#This Row],[Product]],Table6[],2,0) -> CAM | H20: HP | I20: =Table1[[#This Row],[Product Serial Number]] -> AG9447112 | J20: Dell optiplex 390 | K20: i3- 9th Gen, 4GB RAM, 1TB HDD | L20: Windows 10 Professional Service Pack 1, 64 Bit | N20: 34000 | O20: Invoice
A21: =ROW(TagTheAsset!$B21)-ROW(TagTheAsset!$A$1) -> 20 | B21: =Table1[[#This Row],[Tagging No.]] -> MCFLCAM1019 | C21: Owned | D21: Hardware | E21: =Table1[[#This Row],[Product]] -> CCTV Camera | F21: =VLOOKUP(Table5[[#This Row],[Product]],Table6[],2,0) -> CAM | H21: HP | I21: =Table1[[#This Row],[Product Serial Number]] -> AG9447439 | J21: HP Pro 3330 MT | K21: i3-3220 CPU @ 3.30GHZ, 4GB RAM, 500GB HDD | L21: Windows 10 Professional Service Pack 1, 32 Bit | N21: 30476 | O21: Invoice(Desktop Bill)
A22: =ROW(TagTheAsset!$B22)-ROW(TagTheAsset!$A$1) -> 21 | B22: =Table1[[#This Row],[Tagging No.]] -> MCFLCAM1020 | C22: Owned | D22: Hardware | E22: =Table1[[#This Row],[Product]] -> CCTV Camera | F22: =VLOOKUP(Table5[[#This Row],[Product]],Table6[],2,0) -> CAM | H22: HP | I22: =Table1[[#This Row],[Product Serial Number]] -> AG9447209 | J22: HP Pro 3330 MT | K22: i3-3220 CPU @ 3.30GHZ, 2GB RAM, 500GB HDD | L22: Windows 10 Professional Service Pack 1, 32 Bit | N22: 30476 | O22: Invoice(Desktop Bill)
A23: =ROW(TagTheAsset!$B23)-ROW(TagTheAsset!$A$1) -> 22 | B23: =Table1[[#This Row],[Tagging No.]] -> MCFLCAM1021 | C23: Owned | D23: Hardware | E23: =Table1[[#This Row],[Product]] -> CCTV Camera | F23: =VLOOKUP(Table5[[#This Row],[Product]],Table6[],2,0) -> CAM | H23: HP | I23: =Table1[[#This Row],[Product Serial Number]] -> AW0881697 | J23: HP Pro 3330 MT | K23: i3-3220 CPU @ 3.30GHZ, 2GB RAM, 500GB HDD | L23: Windows 10 Professional Service Pack 1, 32 Bit | N23: 30476 | O23: Invoice(Desktop Bill)
A24: =ROW(TagTheAsset!$B24)-ROW(TagTheAsset!$A$1) -> 23 | B24: =Table1[[#This Row],[Tagging No.]] -> MCFLCAM1022 | C24: Owned | D24: Hardware | E24: =Table1[[#This Row],[Product]] -> CCTV Camera | F24: =VLOOKUP(Table5[[#This Row],[Product]],Table6[],2,0) -> CAM | H24: HP | I24: =Table1[[#This Row],[Product Serial Number]] -> AG9447461 | J24: HP Pro 3330 MT | K24: i3-3220 CPU @ 3.30GHZ, 2GB RAM, 500GB HDD | L24: Windows 10 Professional Service Pack 1, 32 Bit | N24: 30476 | O24: Invoice(Desktop Bill)
A25: =ROW(TagTheAsset!$B25)-ROW(TagTheAsset!$A$1) -> 24 | B25: =Table1[[#This Row],[Tagging No.]] -> MCFLCAM1023 | C25: Owned | D25: Hardware | E25: =Table1[[#This Row],[Product]] -> CCTV Camera | F25: =VLOOKUP(Table5[[#This Row],[Product]],Table6[],2,0) -> CAM | H25: HP | I25: =Table1[[#This Row],[Product Serial Number]] -> AG9447455 | J25: HP Pro 3330 MT | K25: i3-3220 CPU @ 3.30GHZ, 2GB RAM, 500GB HDD | L25: Windows 10 Professional Service Pack 1, 32 Bit | N25: 30476 | O25: Invoice(Desktop Bill)
A26: =ROW(TagTheAsset!$B26)-ROW(TagTheAsset!$A$1) -> 25 | B26: =Table1[[#This Row],[Tagging No.]] -> MCFLAS1024 | C26: Owned | D26: Hardware | E26: =Table1[[#This Row],[Product]] -> Alarm System | F26: =VLOOKUP(Table5[[#This Row],[Product]],Table6[],2,0) -> AS | H26: HP | I26: =Table1[[#This Row],[Product Serial Number]] -> Q34225152 | J26: HP Pro 3330 MT | K26: i3-3220 CPU @ 3.30GHZ, 4GB RAM, 500GB HDD | L26: Windows 10 Professional Service Pack 1, 32 Bit | N26: 30476 | O26: Invoice(Desktop Bill)
A27: =ROW(TagTheAsset!$B27)-ROW(TagTheAsset!$A$1) -> 26 | B27: =Table1[[#This Row],[Tagging No.]] -> MCFLSWI1025 | C27: Owned | D27: Hardware | E27: =Table1[[#This Row],[Product]] -> Switch | F27: =VLOOKUP(Table5[[#This Row],[Product]],Table6[],2,0) -> SWI | H27: HP | I27: =Table1[[#This Row],[Product Serial Number]] -> 22352F3003350 | J27: Lenovo Thinkcenter M91P | K27: i5-2400 CPU @ 3.10GHZ,8GB RAM, 320GB | L27: Windows 10 Professional, 64 Bit | N27: 13000 | O27: Invoice(Bhavika Jain Desktop)
A28: =ROW(TagTheAsset!$B28)-ROW(TagTheAsset!$A$1) -> 27 | B28: =Table1[[#This Row],[Tagging No.]] -> MCFLSWI1026 | C28: Owned | D28: Hardware | E28: =Table1[[#This Row],[Product]] -> Switch | F28: =VLOOKUP(Table5[[#This Row],[Product]],Table6[],2,0) -> SWI | H28: HP | I28: =Table1[[#This Row],[Product Serial Number]] -> 2025048231345 | J28: HP Pro 3330 MT | K28: i3-3220 CPU @ 3.30GHZ, 4GB RAM, 500GB HDD | L28: Windows 10 Professional Service Pack 1, 32 Bit | N28: 30476 | O28: Invoice(Desktop Bill)
A29: =ROW(TagTheAsset!$B29)-ROW(TagTheAsset!$A$1) -> 28 | B29: =Table1[[#This Row],[Tagging No.]] -> MCFLBIO1027 | C29: Owned | D29: Hardware | E29: =Table1[[#This Row],[Product]] -> Biomax | F29: =VLOOKUP(Table5[[#This Row],[Product]],Table6[],2,0) -> BIO | H29: Dell | I29: =Table1[[#This Row],[Product Serial Number]] -> AMDB24111500440 | J29: Dell | K29: NA
A30: =ROW(TagTheAsset!$B30)-ROW(TagTheAsset!$A$1) -> 29 | B30: =Table1[[#This Row],[Tagging No.]] -> MCFLBIO1028 | C30: Owned | D30: Hardware | E30: =Table1[[#This Row],[Product]] -> Biomax | F30: =VLOOKUP(Table5[[#This Row],[Product]],Table6[],2,0) -> BIO | H30: Samsung | I30: =Table1[[#This Row],[Product Serial Number]] -> C263449807121C24 | J30: S19C150 | K30: 0301061948AA
A31: =ROW(TagTheAsset!$B31)-ROW(TagTheAsset!$A$1) -> 30 | B31: =Table1[[#This Row],[Tagging No.]] -> MCFLCAM1029 | C31: Owned | D31: Hardware | E31: =Table1[[#This Row],[Product]] -> CCTV Camera | F31: =VLOOKUP(Table5[[#This Row],[Product]],Table6[],2,0) -> CAM | H31: Dell | I31: =Table1[[#This Row],[Product Serial Number]] -> AG9447454 | J31: Dell | K31: NA
A32: =ROW(TagTheAsset!$B32)-ROW(TagTheAsset!$A$1) -> 31 | B32: =Table1[[#This Row],[Tagging No.]] -> MCFLSWI1030 | C32: Owned | D32: Hardware | E32: =Table1[[#This Row],[Product]] -> Switch | F32: =VLOOKUP(Table5[[#This Row],[Product]],Table6[],2,0) -> SWI | H32: Dell | I32: =Table1[[#This Row],[Product Serial Number]] -> 0 | J32: Dell | K32: CN07BN4400540ASE38D6L003R
A33: =ROW(TagTheAsset!$B33)-ROW(TagTheAsset!$A$1) -> 32 | B33: =Table1[[#This Row],[Tagging No.]] -> MCFLLP1031 | C33: Owned | D33: Hardware | E33: =Table1[[#This Row],[Product]] -> Laptop | F33: =VLOOKUP(Table5[[#This Row],[Product]],Table6[],2,0) -> LP | H33: Samsung | I33: =Table1[[#This Row],[Product Serial Number]] -> CY42Z64 | J33: S19C150 | K33: NA
A34: =ROW(TagTheAsset!$B34)-ROW(TagTheAsset!$A$1) -> 33 | B34: =Table1[[#This Row],[Tagging No.]] -> MCFLADP1032 | C34: Owned | D34: Hardware | E34: =Table1[[#This Row],[Product]] -> Adaptor | F34: =VLOOKUP(Table5[[#This Row],[Product]],Table6[],2,0) -> ADP | H34: Samsung | I34: =Table1[[#This Row],[Product Serial Number]] -> CN-07JHD3-CH600-4AE-0AZI-A02 | J34: S19C150 | K34: NA
A35: =ROW(TagTheAsset!$B35)-ROW(TagTheAsset!$A$1) -> 34 | B35: =Table1[[#This Row],[Tagging No.]] -> MCFLLP1033 | C35: Owned | D35: Hardware | E35: =Table1[[#This Row],[Product]] -> Laptop | F35: =VLOOKUP(Table5[[#This Row],[Product]],Table6[],2,0) -> LP | H35: Dell | I35: =Table1[[#This Row],[Product Serial Number]] -> G5MDT74 | J35: Dell | K35: CN07BN4400540ASE38D6L0110
A36: =ROW(TagTheAsset!$B36)-ROW(TagTheAsset!$A$1) -> 35 | B36: =Table1[[#This Row],[Tagging No.]] -> MCFLADP1034 | C36: Owned | D36: Hardware | E36: =Table1[[#This Row],[Product]] -> Adaptor | F36: =VLOOKUP(Table5[[#This Row],[Product]],Table6[],2,0) -> ADP | H36: Samsung | I36: =Table1[[#This Row],[Product Serial Number]] -> CN-07JHD3-CH600-4C9-0HW0-A02 | J36: S19C150
A37: =ROW(TagTheAsset!$B37)-ROW(TagTheAsset!$A$1) -> 36 | B37: =Table1[[#This Row],[Tagging No.]] -> MCFLLP1035 | C37: Owned | D37: Hardware | E37: =Table1[[#This Row],[Product]] -> Laptop | F37: =VLOOKUP(Table5[[#This Row],[Product]],Table6[],2,0) -> LP | H37: Samsung | I37: =Table1[[#This Row],[Product Serial Number]] -> 3NVHY64 | J37: S19C150 | K37: CN07BN4400540ASE38D6L011J
A38: =ROW(TagTheAsset!$B38)-ROW(TagTheAsset!$A$1) -> 37 | B38: =Table1[[#This Row],[Tagging No.]] -> MCFLADP1036 | C38: Owned | D38: Hardware | E38: =Table1[[#This Row],[Product]] -> Adaptor | F38: =VLOOKUP(Table5[[#This Row],[Product]],Table6[],2,0) -> ADP | H38: Samsung | I38: =Table1[[#This Row],[Product Serial Number]] -> CN-03PHNW-LOC00-4AI-0BB3-A02 | J38: S19C150 | K38: N1151430
A39: =ROW(TagTheAsset!$B39)-ROW(TagTheAsset!$A$1) -> 38 | B39: =Table1[[#This Row],[Tagging No.]] -> MCFLLP1037 | C39: Owned | D39: Hardware | E39: =Table1[[#This Row],[Product]] -> Laptop | F39: =VLOOKUP(Table5[[#This Row],[Product]],Table6[],2,0) -> LP | H39: Samsung | I39: =Table1[[#This Row],[Product Serial Number]] -> 58WVX64 | J39: S19C150 | K39: 0301061948AA
A40: =ROW(TagTheAsset!$B40)-ROW(TagTheAsset!$A$1) -> 39 | B40: =Table1[[#This Row],[Tagging No.]] -> MCFLADP1038 | C40: Owned | D40: Hardware | E40: =Table1[[#This Row],[Product]] -> Adaptor | F40: =VLOOKUP(Table5[[#This Row],[Product]],Table6[],2,0) -> ADP | H40: Dell | I40: =Table1[[#This Row],[Product Serial Number]] -> CN-0G4G24-DES00-495-EMOI-A02 | J40: Dell
A41: =ROW(TagTheAsset!$B41)-ROW(TagTheAsset!$A$1) -> 40 | B41: =Table1[[#This Row],[Tagging No.]] -> MCFLLP1039 | C41: Owned | D41: Hardware | E41: =Table1[[#This Row],[Product]] -> Laptop | F41: =VLOOKUP(Table5[[#This Row],[Product]],Table6[],2,0) -> LP | H41: Samsung | I41: =Table1[[#This Row],[Product Serial Number]] -> 4ZSC864 | J41: S19C150 | K41: NA
A42: =ROW(TagTheAsset!$B42)-ROW(TagTheAsset!$A$1) -> 41 | B42: =Table1[[#This Row],[Tagging No.]] -> MCFLADP1040 | C42: Owned | D42: Hardware | E42: =Table1[[#This Row],[Product]] -> Adaptor | F42: =VLOOKUP(Table5[[#This Row],[Product]],Table6[],2,0) -> ADP | H42: Samsung | I42: =Table1[[#This Row],[Product Serial Number]] -> CN-07JHD3-CH600-494-0UUN-A02 | J42: S19C150 | K42: NA
...

Sheet Transaction
A1: Sr. No. | B1: Tag No. | C1: Error check | D1: Date of Transaction | E1: Type of Transaction | F1: Location From | G1: User From | H1: Location To | I1: User To | J1: Department | K1: Emp/VendorCode | L1: Reference Type | M1: Date of Reference | N1: Approved By
A2: 1 | B2: MCFLHO20201011000 | C2: MCFLHO20201011000 | D2: 44059 | E2: Addition | F2: HO | G2: HO | H2: HO | I2: Smita | J2: Accounts | L2: Invoice | N2: HOD
A3: =A2+1 -> 2 | B3: MCFLHO20131011001 | C3: MCFLHO20131011001 | D3: 41542 | E3: Opening Stock | L3: Invoice
A4: =A3+1 -> 3 | B4: MCFLHO20201011002 | C4: MCFLHO20201011002 | D4: 44059 | E4: Addition | L4: Proforma Invoice
A5: =A4+1 -> 4 | B5: MCFLHO20201011003 | C5: MCFLHO20201011003 | D5: 44059 | E5: Addition
A6: =A5+1 -> 5 | B6: MCFLHO20131011004 | C6: MCFLHO20131011004 | D6: 41542 | E6: Opening Stock
A7: =A6+1 -> 6 | B7: MCFLHO20131011005 | C7: MCFLHO20131011005 | D7: 41542 | E7: Opening Stock
A8: =A7+1 -> 7 | B8: MCFLHO20201011006 | C8: MCFLHO20201011006 | D8: 44059 | E8: Addition
A9: =A8+1 -> 8 | B9: MCFLHO20131011007 | C9: MCFLHO20131011007 | D9: 41542 | E9: Opening Stock
A10: =A9+1 -> 9 | B10: MCFLHO20131011008 | C10: MCFLHO20131011008 | D10: 41542 | E10: Opening Stock
A11: =A10+1 -> 10 | B11: MCFLHO20131011009 | C11: MCFLHO20131011009 | D11: 41542 | E11: Opening Stock
A12: =A11+1 -> 11 | B12: MCFLHO20131011010 | C12: MCFLHO20131011010 | D12: 41542 | E12: Opening Stock
A13: =A12+1 -> 12 | B13: MCFLHO20201011011 | C13: MCFLHO20201011011 | D13: 44059 | E13: Addition
A14: =A13+1 -> 13 | B14: MCFLHO20131011012 | C14: MCFLHO20131011012 | D14: 41542 | E14: Opening Stock
A15: =A14+1 -> 14 | B15: MCFLHO20131011013 | C15: MCFLHO20131011013 | D15: 41542 | E15: Opening Stock
A16: =A15+1 -> 15 | B16: MCFLHO20131011014 | C16: MCFLHO20131011014 | D16: 41542 | E16: Opening Stock
... A114: =A113+1 -> 113 | B114: MCFLHO20191051112 | C114: MCFLHO20191051112 | D114: 43488 | E114: Addition
A115: =A114+1 -> 114 | B115: MCFLHO20151051113 | C115: MCFLHO20151051113 | D115: 42125
A116: =A115+1 -> 115 | B116: MCFLHO20191051114 | C116: MCFLHO20191051114 | D116: 43664 | E116: Addition
A117: =A116+1 -> 116 | B117: MCFLHO20191051115 | C117: MCFLHO20191051115 | D117: 43663 | E117: Addition
A118: =A117+1 -> 117 | B118: MCFLHO20151051116 | C118: MCFLHO20151051116 | D118: 42125 | E118: Opening Stock
A119: =A118+1 -> 118 | B119: MCFLHO20151051117 | C119: MCFLHO20151051117 | D119: 42125 | E119: Opening Stock
A120: =A119+1 -> 119 | B120: MCFLHO20151051118 | C120: MCFLHO20151051118 | D120: 42125 | E120: Opening Stock
A121: =A120+1 -> 120 | B121: MCFLHO20151051119 | C121: MCFLHO20151051119 | D121: 42125 | E121: Opening Stock
A122: =A121+1 -> 121 | B122: MCFLHO20151051120 | C122: MCFLHO20151051120 | D122: 42125 | E122: Opening Stock
A123: =A122+1 -> 122 | B123: MCFLHO20151051121 | C123: MCFLHO20151051121 | D123: 42125 | E123: Opening Stock
A124: =A123+1 -> 123 | B124: MCFLHO20191051122 | C124: MCFLHO20191051122 | D124: 43488 | E124: Addition
A125: =A124+1 -> 124 | B125: MCFLHO20191051123 | C125: MCFLHO20191051123 | D125: 43735 | E125: Addition
A126: =A125+1 -> 125 | B126: MCFLHO20191051124 | C126: MCFLHO20191051124 | D126: 43637 | E126: Addition
A127: =A126+1 -> 126 | B127: MCFLHO20151051125 | C127: MCFLHO20151051125 | D127: 42125 | E127: Opening Stock
... A201: =A200+1 -> 200 | B201: MCFLHO20211061199 | C201: MCFLHO20211061199 | D201: 44268 | E201: Addition
B202: MCFLHO20201051200 | C202: MCFLHO20201051200 | D202: 44089 | E202: Addition
B203: MCFLHO20201061201 | C203: MCFLHO20201061201 | D203: 44089 | E203: Addition
B204: MCFLHO20201051202 | C204: MCFLHO20201051202 | D204: 43892 | E204: Addition
B205: MCFLHO20201061203 | C205: MCFLHO20201061203 | D205: 43892 | E205: Addition
B206: MCFLHO20201051204 | C206: MCFLHO20201051204 | D206: 43892 | E206: Addition
B207: MCFLHO20201061205 | C207: MCFLHO20201061205 | D207: 43892 | E207: Addition
B208: SHPLHO20201051206 | C208: SHPLHO20201051206 | D208: 44027 | E208: Addition
B209: SHPLHO20201061207 | C209: SHPLHO20201061207 | D209: 44027 | E209: Addition

Sheet Item wise Report
A2: Date of Transaction
A4: Product Code | B4: Product | C4: Qty | D4: Opening Stock | E4: Additions | F4: Transfer | G4: Sold/Expired2 | H4: Scrap | I4: Closing Stock2
B5: CPU | I5: =Table3[[#This Row],[Opening Stock]]+Table3[[#This Row],[Additions]]-Table3[[#This Row],[Transfer]]-Table3[[#This Row],[Sold/Expired2]]-Table3[[#This Row],[Scrap]] -> 0
B6: Desktop/monitor | I6: =Table3[[#This Row],[Opening Stock]]+Table3[[#This Row],[Additions]]-Table3[[#This Row],[Transfer]]-Table3[[#This Row],[Sold/Expired2]]-Table3[[#This Row],[Scrap]] -> 0
B7: Mouse | I7: =Table3[[#This Row],[Opening Stock]]+Table3[[#This Row],[Additions]]-Table3[[#This Row],[Transfer]]-Table3[[#This Row],[Sold/Expired2]]-Table3[[#This Row],[Scrap]] -> 0
B8: Keyboard | I8: =Table3[[#This Row],[Opening Stock]]+Table3[[#This Row],[Additions]]-Table3[[#This Row],[Transfer]]-Table3[[#This Row],[Sold/Expired2]]-Table3[[#This Row],[Scrap]] -> 0
B9: Laptop | I9: =Table3[[#This Row],[Opening Stock]]+Table3[[#This Row],[Additions]]-Table3[[#This Row],[Transfer]]-Table3[[#This Row],[Sold/Expired2]]-Table3[[#This Row],[Scrap]] -> 0
B10: Adaptor | I10: =Table3[[#This Row],[Opening Stock]]+Table3[[#This Row],[Additions]]-Table3[[#This Row],[Transfer]]-Table3[[#This Row],[Sold/Expired2]]-Table3[[#This Row],[Scrap]] -> 0
B11: Printer | I11: =Table3[[#This Row],[Opening Stock]]+Table3[[#This Row],[Additions]]-Table3[[#This Row],[Transfer]]-Table3[[#This Row],[Sold/Expired2]]-Table3[[#This Row],[Scrap]] -> 0
B12: Scanner | I12: =Table3[[#This Row],[Opening Stock]]+Table3[[#This Row],[Additions]]-Table3[[#This Row],[Transfer]]-Table3[[#This Row],[Sold/Expired2]]-Table3[[#This Row],[Scrap]] -> 0
B13: Phone | I13: =Table3[[#This Row],[Opening Stock]]+Table3[[#This Row],[Additions]]-Table3[[#This Row],[Transfer]]-Table3[[#This Row],[Sold/Expired2]]-Table3[[#This Row],[Scrap]] -> 0
B14: Sim Card | I14: =Table3[[#This Row],[Opening Stock]]+Table3[[#This Row],[Additions]]-Table3[[#This Row],[Transfer]]-Table3[[#This Row],[Sold/Expired2]]-Table3[[#This Row],[Scrap]] -> 0
B15: CCTV | I15: =Table3[[#This Row],[Opening Stock]]+Table3[[#This Row],[Additions]]-Table3[[#This Row],[Transfer]]-Table3[[#This Row],[Sold/Expired2]]-Table3[[#This Row],[Scrap]] -> 0
I16: =Table3[[#This Row],[Opening Stock]]+Table3[[#This Row],[Additions]]-Table3[[#This Row],[Transfer]]-Table3[[#This Row],[Sold/Expired2]]-Table3[[#This Row],[Scrap]] -> 0
I17: =Table3[[#This Row],[Opening Stock]]+Table3[[#This Row],[Additions]]-Table3[[#This Row],[Transfer]]-Table3[[#This Row],[Sold/Expired2]]-Table3[[#This Row],[Scrap]] -> 0
I18: =Table3[[#This Row],[Opening Stock]]+Table3[[#This Row],[Additions]]-Table3[[#This Row],[Transfer]]-Table3[[#This Row],[Sold/Expired2]]-Table3[[#This Row],[Scrap]] -> 0
I19: =Table3[[#This Row],[Opening Stock]]+Table3[[#This Row],[Additions]]-Table3[[#This Row],[Transfer]]-Table3[[#This Row],[Sold/Expired2]]-Table3[[#This Row],[Scrap]] -> 0
I20: =Table3[[#This Row],[Opening Stock]]+Table3[[#This Row],[Additions]]-Table3[[#This Row],[Transfer]]-Table3[[#This Row],[Sold/Expired2]]-Table3[[#This Row],[Scrap]] -> 0

Sheet Location Wise Report
A1: Location Code | B1: Location | C1: Opening Stock | D1: Additions | E1: Sold/Expired | F1: Scrap | G1: Closing Stock
B2: MCFL-HO
B3: Vile Parle
